<?xml version="1.0"?>
<robot xmlns:xacro="http://www.ros.org/wiki/xacro" >
    <xacro:include filename="inertial_macros.xacro"/>
    <xacro:macro name="wheel" params="radius width mass pos origin">

        <joint name="wheel_joint_${pos}" type="continuous">
            <parent link="chassis"/>
            <child link="wheel_${pos}"/>
            <origin xyz="${origin}" rpy="-${pi/2} 0 0"/>
            <axis xyz="0 0 1"/>
        </joint>

        <link name="wheel_${pos}">
            <visual>
                <geometry>
                    <cylinder length="${width}" radius="${radius}"/>
                </geometry>
                <material name = "black"/>
            </visual>
            <collision>
                <geometry>
                    <cylinder length="${width}" radius="${radius}"/>
                </geometry>
            </collision>
            <xacro:inertial_cylinder mass="0.1" length="0.02" radius="0.05">
                <origin xyz = "0 0 0" rpy="0 0 0"/>
            </xacro:inertial_cylinder>
        </link>

        <gazebo reference="wheel_${pos}">
            <material>Gazebo/Black</material>
            <mu1>0.2</mu1>
            <mu2>0.2</mu2>
        </gazebo>
    </xacro:macro>

</robot>

        
